Workbook
Name Срез_Годы__дата_создания_чека: #N/A
Name Срез_Категория: #N/A
Name Срез_Кварталы__дата_создания_чека: #N/A
Name Срез_магазин_покупки: #N/A
Name Срез_Месяцы__дата_создания_чека: #N/A
Name Срез_Поставщик: #N/A
Name Срез_Страна: #N/A
Name Срез_участие_в_программе_лояльности: #N/A

Sheet интро
C3: Исследование выполнила: Светлана Насонкова
C4: Данные сгенерированы ChatGPT и не являются NDA
C6: Задачи исследования | D6: № | E6: Декомпозиция | F6: Выводы исследования
C7: Анализ продаж продуктовых сетей | D7: 1 | E7: Динамика продаж по магазинам | F7: Динамика продаж с января 2023г. по май 2024 г. характеризуется значительными колебаниями. В 2023 г. особенно сильная просадка продаж наблюдается в октябре - до 185 800 у.е. Пик продаж пришелся на март 2024 и достиг 299 875 у.е., что может быть связано с успешно проведенными акциями или запуском нового продукта. Затем наблюдался спад продаж и к маю 2024г. продажи достигли своего минимума 118 215 у.е. (-181 660 у.е. за 2 месяца), что связано с отсутствием в мае 2024 г. данных о продажах 8 ТС (Мосмарт, Верный, Седьмой Континент, Бристоль, Мираторг, Магнит, Дикси, Пятёрочка).
D8: 2 | E8: Анализ цен внутри товарной категории по магазинам | F8: Отклонение от средней цены варьируются от 10% (наценка) до -10% (скидка), что указывает на значительные различия в ценовой политике по магазинам. С наибольшим дисконтом товары продаются в ТС Пятерочка - там средний цены на 10% ниже. И наоборот, в среднем на 10% выше цены в ТС Лента.
D9: 3 | E9: Суммарные продажи по магазинам | F9: Среди продуктовых сетей лидером по продажам стала ТС О'кей c GMV 264 220 у.е., наименьшие продажи у ТС Билла - 136 375 у.е.
C10: Сравнение поставщиков по объемам закупок | D10: 4 | E10: Анализ цен внутри категории по поставщикам | F10: Наиболее высокие средние цены в категории фрукты от поставщика Green Garden - 369,2 у.е., наименьшие - в категории колбаса от поставщика Микоян - 82 у.е.
D11: 5 | E11: Суммарные продажи по поставщикам | F11: По поставщикам довольно большой разброс значений GMV: наибольшие суммарные продажи у Паста Зара - 147 150 у.е., наименьшие у Микоян - 410 у.е.
C12: Изучение продаж по категориям товаров | D12: 6 | E12: Суммарные продажи по категориям | F12: Наибольшие суммарные продажи в категории "Макароны" - 334 725 у.е., наименьшие - в категории "Колбаса" - 106 565 у.е.
D13: 7 | E13: Среднее кол-во по категориям (что покупают чаще) | F13: В среднем за одну покупку покупатели берут больше всего товары из категории "Молоко" - 3,2 шт, меньше всего покупают товаров из категории "Сыр" - 2,6 ед.
C14: Изучение клиентов по географии и лайфтайму | D14: 8 | E14: Аналитика географии клиентов | F14: Большинство клиентов торговых сетей из России - 34% от общего числа клиентов или 146 чел., меньше всего из Беларуси - 12% или 51 чел.
D15: 9 | E15: Кол-во дней с момента регистрации до покупки | F15: Большинство клиентов, совершивших покупку были зарегистрированы от 308 до 607 дней назад, т.е. примерно от 10 мес. до 20 мес. назад.
D16: 10 | E16: Лайфтайм клиента | F16: Наибольшее число клиентов были зарегистрированы в период 15-17 месяцев, наименьшее в 1-3 месяца
D17: 11 | E17: Частотность имен для рекламной компании | F17: Топ 8 имен клиентов: Василиса, Феврония, Алевтина, Эмилия, Марфа, Любовь, Вера, Жанна.
D18: 12 | E18: Платежеспособность по странам | F18: Наиболее существенные денежные средства поступили из России - 31% от всех поступлений или 1 256 650 у.е. Меньше всего пришло денежных средств из Беларуси - 12% или 493 965 у.е.
C20: Отработка Hard Skills
C21: Преобразование типов и визуальное форматирование
C22: Условное форматирование данных
C23: Умные таблицы и работа с абсолютными и относительными ссылками
C24: Математические и текстовые функции
C25: Функции для работы с датой и временем
C26: Функции поиска и извлечения данных
C27: Сводные таблицы и срезы данных
C28: Построение диаграмм и дашборда

Sheet Дашборд
C3: ОБЩИЙ GMV | I3: КОЛИЧЕСТВО ПОКУПОК | O3: ТОП ПОСТАВЩИК ПО GMV | U3: ТОП МАГАЗИН ПО GMV | AA3: ТОП КАТЕГОРИЯ
C4: =SUM('GMV по магазинам'!B2:B23) -> 4002165 | I4: =SUM('кол-во дней с регистрации'!B:B) -> 1000 | O4: ='GMV по поставщикам'!A4 -> Паста Зара | U4: ='GMV по магазинам'!A4 -> О'кей | AA4: ='GMV по категориям'!A4 -> Макароны
B7: Анализ продаж продуктовых сетей
B70: Сравнение поставщиков по объемам закупок
B135: Изучение продаж по категориям товаров
B193: Изучение клиентов по географии и лайфтайму

Sheet продажи
A1: id чека | B1: id товара | C1: цена за шт в рублях | D1: кол-во штук в чеке | E1: сумма чека | F1: дата создания чека | G1: магазин покупки | H1: id клиента | I1: Категория | J1: Средняя цена в категории за шт | K1: Выгода для клиента | L1: Поставщик | M1: Средняя цена в категории за шт по поставщику | N1: Выгода по поставщикам | O1: Дата регистрации | P1: Количество дней с момента регистрации | Q1: Страна | R1: ID уникальный | S1: участие в программе лояльности | T1: лайфтайм клиента
A2: 1 | B2: 300 | C2: 103 | D2: 4 | E2: 2060 | F2: 45187 | G2: Бристоль | H2: 315 | I2: =VLOOKUP(Продажи[[#This Row],[id товара]],Товары[],2,0) -> Сахар | J2: =AVERAGEIF(Продажи[Категория],Продажи[[#This Row],[Категория]],Продажи[цена за шт в рублях]) -> 252.76271 | K2: =Продажи[[#This Row],[цена за шт в рублях]]/Продажи[[#This Row],[Средняя цена в категории за шт]]-1 -> -0.59250319 | L2: =VLOOKUP(Продажи[[#This Row],[id товара]],Товары[],3,0) -> Продимекс | M2: =AVERAGEIFS(Продажи[цена за шт в рублях],Продажи[Категория],Продажи[[#This Row],[Категория]],Продажи[Поставщик],Продажи[[#This Row],[Поставщик]]) -> 240.5 | N2: =Продажи[[#This Row],[цена за шт в рублях]]/Продажи[[#This Row],[Средняя цена в категории за шт по поставщику]]-1 -> -0.57172557 | O2: =VLOOKUP(Продажи[[#This Row],[id клиента]],клиенты!$A$2:$E$435,5,0) -> 44747 | P2: =Продажи[[#This Row],[дата создания чека]]-Продажи[[#This Row],[Дата регистрации]] -> 440 | Q2: =VLOOKUP(Продажи[[#This Row],[id клиента]],клиенты!$A$2:$G$435,7,0) -> Узбекистан | R2: =IF(COUNTIF($H$2:H2, H2)=1, 1, 0) -> 1 | S2: =VLOOKUP(Продажи[[#This Row],[id клиента]],клиенты!$A$2:$D$435,4,0) -> да | T2: =VLOOKUP(Продажи[[#This Row],[id клиента]],клиенты!$A$2:$I$435,9,0) -> 20.402464
A3: 2 | B3: 486 | C3: 296 | D3: 3 | E3: 4440 | F3: 45083 | G3: Дикси | H3: 253 | I3: =VLOOKUP(Продажи[[#This Row],[id товара]],Товары[],2,0) -> Соль | J3: =AVERAGEIF(Продажи[Категория],Продажи[[#This Row],[Категория]],Продажи[цена за шт в рублях]) -> 264.86792 | K3: =Продажи[[#This Row],[цена за шт в рублях]]/Продажи[[#This Row],[Средняя цена в категории за шт]]-1 -> 0.11753811 | L3: =VLOOKUP(Продажи[[#This Row],[id товара]],Товары[],3,0) -> Илецкая | M3: =AVERAGEIFS(Продажи[цена за шт в рублях],Продажи[Категория],Продажи[[#This Row],[Категория]],Продажи[Поставщик],Продажи[[#This Row],[Поставщик]]) -> 238.16667 | N3: =Продажи[[#This Row],[цена за шт в рублях]]/Продажи[[#This Row],[Средняя цена в категории за шт по поставщику]]-1 -> 0.24282715 | O3: =VLOOKUP(Продажи[[#This Row],[id клиента]],клиенты!$A$2:$E$435,5,0) -> 44750 | P3: =Продажи[[#This Row],[дата создания чека]]-Продажи[[#This Row],[Дата регистрации]] -> 333 | Q3: =VLOOKUP(Продажи[[#This Row],[id клиента]],клиенты!$A$2:$G$435,7,0) -> Беларусь | R3: =IF(COUNTIF($H$2:H3, H3)=1, 1, 0) -> 1 | S3: =VLOOKUP(Продажи[[#This Row],[id клиента]],клиенты!$A$2:$D$435,4,0) -> да | T3: =VLOOKUP(Продажи[[#This Row],[id клиента]],клиенты!$A$2:$I$435,9,0) -> 10.940452
A4: 3 | B4: 76 | C4: 139 | D4: 5 | E4: 3475 | F4: 45363 | G4: Городской Супермаркет | H4: 12 | I4: =VLOOKUP(Продажи[[#This Row],[id товара]],Товары[],2,0) -> Печенье | J4: =AVERAGEIF(Продажи[Категория],Продажи[[#This Row],[Категория]],Продажи[цена за шт в рублях]) -> 283.46809 | K4: =Продажи[[#This Row],[цена за шт в рублях]]/Продажи[[#This Row],[Средняя цена в категории за шт]]-1 -> -0.50964497 | L4: =VLOOKUP(Продажи[[#This Row],[id товара]],Товары[],3,0) -> Юбилейное | M4: =AVERAGEIFS(Продажи[цена за шт в рублях],Продажи[Категория],Продажи[[#This Row],[Категория]],Продажи[Поставщик],Продажи[[#This Row],[Поставщик]]) -> 232.44444 | N4: =Продажи[[#This Row],[цена за шт в рублях]]/Продажи[[#This Row],[Средняя цена в категории за шт по поставщику]]-1 -> -0.40200765 | O4: =VLOOKUP(Продажи[[#This Row],[id клиента]],клиенты!$A$2:$E$435,5,0) -> 44842 | P4: =Продажи[[#This Row],[дата создания чека]]-Продажи[[#This Row],[Дата регистрации]] -> 521 | Q4: =VLOOKUP(Продажи[[#This Row],[id клиента]],клиенты!$A$2:$G$435,7,0) -> Беларусь | R4: =IF(COUNTIF($H$2:H4, H4)=1, 1, 0) -> 1 | S4: =VLOOKUP(Продажи[[#This Row],[id клиента]],клиенты!$A$2:$D$435,4,0) -> да | T4: =VLOOKUP(Продажи[[#This Row],[id клиента]],клиенты!$A$2:$I$435,9,0) -> 17.117043
A5: 4 | B5: 240 | C5: 141 | D5: 5 | E5: 3525 | F5: 45262 | G5: Верный | H5: 116 | I5: =VLOOKUP(Продажи[[#This Row],[id товара]],Товары[],2,0) -> Макароны | J5: =AVERAGEIF(Продажи[Категория],Продажи[[#This Row],[Категория]],Продажи[цена за шт в рублях]) -> 265.47674 | K5: =Продажи[[#This Row],[цена за шт в рублях]]/Продажи[[#This Row],[Средняя цена в категории за шт]]-1 -> -0.46888003 | L5: =VLOOKUP(Продажи[[#This Row],[id товара]],Товары[],3,0) -> Борилла | M5: =AVERAGEIFS(Продажи[цена за шт в рублях],Продажи[Категория],Продажи[[#This Row],[Категория]],Продажи[Поставщик],Продажи[[#This Row],[Поставщик]]) -> 236.27586 | N5: =Продажи[[#This Row],[цена за шт в рублях]]/Продажи[[#This Row],[Средняя цена в категории за шт по поставщику]]-1 -> -0.40323993 | O5: =VLOOKUP(Продажи[[#This Row],[id клиента]],клиенты!$A$2:$E$435,5,0) -> 44643 | P5: =Продажи[[#This Row],[дата создания чека]]-Продажи[[#This Row],[Дата регистрации]] -> 619 | Q5: =VLOOKUP(Продажи[[#This Row],[id клиента]],клиенты!$A$2:$G$435,7,0) -> Россия | R5: =IF(COUNTIF($H$2:H5, H5)=1, 1, 0) -> 1 | S5: =VLOOKUP(Продажи[[#This Row],[id клиента]],клиенты!$A$2:$D$435,4,0) -> нет | T5: =VLOOKUP(Продажи[[#This Row],[id клиента]],клиенты!$A$2:$I$435,9,0) -> 21.125257
A6: 5 | B6: 32 | C6: 123 | D6: 2 | E6: 1230 | F6: 45151 | G6: Спар | H6: 471 | I6: =VLOOKUP(Продажи[[#This Row],[id товара]],Товары[],2,0) -> Овощи | J6: =AVERAGEIF(Продажи[Категория],Продажи[[#This Row],[Категория]],Продажи[цена за шт в рублях]) -> 250.4878 | K6: =Продажи[[#This Row],[цена за шт в рублях]]/Продажи[[#This Row],[Средняя цена в категории за шт]]-1 -> -0.50895813 | L6: =VLOOKUP(Продажи[[#This Row],[id товара]],Товары[],3,0) -> Зеленая грядка | M6: =AVERAGEIFS(Продажи[цена за шт в рублях],Продажи[Категория],Продажи[[#This Row],[Категория]],Продажи[Поставщик],Продажи[[#This Row],[Поставщик]]) -> 159.2 | N6: =Продажи[[#This Row],[цена за шт в рублях]]/Продажи[[#This Row],[Средняя цена в категории за шт по поставщику]]-1 -> -0.22738693 | O6: =VLOOKUP(Продажи[[#This Row],[id клиента]],клиенты!$A$2:$E$435,5,0) -> 44577 | P6: =Продажи[[#This Row],[дата создания чека]]-Продажи[[#This Row],[Дата регистрации]] -> 574 | Q6: =VLOOKUP(Продажи[[#This Row],[id клиента]],клиенты!$A$2:$G$435,7,0) -> Украина | R6: =IF(COUNTIF($H$2:H6, H6)=1, 1, 0) -> 1 | S6: =VLOOKUP(Продажи[[#This Row],[id клиента]],клиенты!$A$2:$D$435,4,0) -> да | T6: =VLOOKUP(Продажи[[#This Row],[id клиента]],клиенты!$A$2:$I$435,9,0) -> 18.858316
A7: 6 | B7: 162 | C7: 452 | D7: 2 | E7: 4520 | F7: 45281 | G7: Бристоль | H7: 374 | I7: =VLOOKUP(Продажи[[#This Row],[id товара]],Товары[],2,0) -> Сок | J7: =AVERAGEIF(Продажи[Категория],Продажи[[#This Row],[Категория]],Продажи[цена за шт в рублях]) -> 268.60345 | K7: =Продажи[[#This Row],[цена за шт в рублях]]/Продажи[[#This Row],[Средняя цена в категории за шт]]-1 -> 0.6827781 | L7: =VLOOKUP(Продажи[[#This Row],[id товара]],Товары[],3,0) -> Фруктовый сад | M7: =AVERAGEIFS(Продажи[цена за шт в рублях],Продажи[Категория],Продажи[[#This Row],[Категория]],Продажи[Поставщик],Продажи[[#This Row],[Поставщик]]) -> 281.96875 | N7: =Продажи[[#This Row],[цена за шт в рублях]]/Продажи[[#This Row],[Средняя цена в категории за шт по поставщику]]-1 -> 0.60301452 | O7: =VLOOKUP(Продажи[[#This Row],[id клиента]],клиенты!$A$2:$E$435,5,0) -> 44582 | P7: =Продажи[[#This Row],[дата создания чека]]-Продажи[[#This Row],[Дата регистрации]] -> 699 | Q7: =VLOOKUP(Продажи[[#This Row],[id клиента]],клиенты!$A$2:$G$435,7,0) -> Украина | R7: =IF(COUNTIF($H$2:H7, H7)=1, 1, 0) -> 1 | S7: =VLOOKUP(Продажи[[#This Row],[id клиента]],клиенты!$A$2:$D$435,4,0) -> нет | T7: =VLOOKUP(Продажи[[#This Row],[id клиента]],клиенты!$A$2:$I$435,9,0) -> 23.326489
A8: 7 | B8: 323 | C8: 149 | D8: 5 | E8: 3725 | F8: 45349 | G8: Карусель | H8: 477 | I8: =VLOOKUP(Продажи[[#This Row],[id товара]],Товары[],2,0) -> Рыба | J8: =AVERAGEIF(Продажи[Категория],Продажи[[#This Row],[Категория]],Продажи[цена за шт в рублях]) -> 258.51282 | K8: =Продажи[[#This Row],[цена за шт в рублях]]/Продажи[[#This Row],[Средняя цена в категории за шт]]-1 -> -0.42362626 | L8: =VLOOKUP(Продажи[[#This Row],[id товара]],Товары[],3,0) -> Меридиан | M8: =AVERAGEIFS(Продажи[цена за шт в рублях],Продажи[Категория],Продажи[[#This Row],[Категория]],Продажи[Поставщик],Продажи[[#This Row],[Поставщик]]) -> 260.64706 | N8: =Продажи[[#This Row],[цена за шт в рублях]]/Продажи[[#This Row],[Средняя цена в категории за шт по поставщику]]-1 -> -0.42834575 | O8: =VLOOKUP(Продажи[[#This Row],[id клиента]],клиенты!$A$2:$E$435,5,0) -> 44738 | P8: =Продажи[[#This Row],[дата создания чека]]-Продажи[[#This Row],[Дата регистрации]] -> 611 | Q8: =VLOOKUP(Продажи[[#This Row],[id клиента]],клиенты!$A$2:$G$435,7,0) -> Узбекистан | R8: =IF(COUNTIF($H$2:H8, H8)=1, 1, 0) -> 1 | S8: =VLOOKUP(Продажи[[#This Row],[id клиента]],клиенты!$A$2:$D$435,4,0) -> да | T8: =VLOOKUP(Продажи[[#This Row],[id клиента]],клиенты!$A$2:$I$435,9,0) -> 20.073922
A9: 8 | B9: 60 | C9: 489 | D9: 4 | E9: 9780 | F9: 45327 | G9: Мираторг | H9: 335 | I9: =VLOOKUP(Продажи[[#This Row],[id товара]],Товары[],2,0) -> Кофе | J9: =AVERAGEIF(Продажи[Категория],Продажи[[#This Row],[Категория]],Продажи[цена за шт в рублях]) -> 249.02381 | K9: =Продажи[[#This Row],[цена за шт в рублях]]/Продажи[[#This Row],[Средняя цена в категории за шт]]-1 -> 0.96366765 | L9: =VLOOKUP(Продажи[[#This Row],[id товара]],Товары[],3,0) -> Jacobs | M9: =AVERAGEIFS(Продажи[цена за шт в рублях],Продажи[Категория],Продажи[[#This Row],[Категория]],Продажи[Поставщик],Продажи[[#This Row],[Поставщик]]) -> 276.21053 | N9: =Продажи[[#This Row],[цена за шт в рублях]]/Продажи[[#This Row],[Средняя цена в категории за шт по поставщику]]-1 -> 0.77038872 | O9: =VLOOKUP(Продажи[[#This Row],[id клиента]],клиенты!$A$2:$E$435,5,0) -> 44619 | P9: =Продажи[[#This Row],[дата создания чека]]-Продажи[[#This Row],[Дата регистрации]] -> 708 | Q9: =VLOOKUP(Продажи[[#This Row],[id клиента]],клиенты!$A$2:$G$435,7,0) -> Узбекистан | R9: =IF(COUNTIF($H$2:H9, H9)=1, 1, 0) -> 1 | S9: =VLOOKUP(Продажи[[#This Row],[id клиента]],клиенты!$A$2:$D$435,4,0) -> нет | T9: =VLOOKUP(Продажи[[#This Row],[id клиента]],клиенты!$A$2:$I$435,9,0) -> 23.26078
A10: 9 | B10: 401 | C10: 416 | D10: 5 | E10: 10400 | F10: 45376 | G10: Мосмарт | H10: 350 | I10: =VLOOKUP(Продажи[[#This Row],[id товара]],Товары[],2,0) -> Чай | J10: =AVERAGEIF(Продажи[Категория],Продажи[[#This Row],[Категория]],Продажи[цена за шт в рублях]) -> 271.18182 | K10: =Продажи[[#This Row],[цена за шт в рублях]]/Продажи[[#This Row],[Средняя цена в категории за шт]]-1 -> 0.53402615 | L10: =VLOOKUP(Продажи[[#This Row],[id товара]],Товары[],3,0) -> Greenfield | M10: =AVERAGEIFS(Продажи[цена за шт в рублях],Продажи[Категория],Продажи[[#This Row],[Категория]],Продажи[Поставщик],Продажи[[#This Row],[Поставщик]]) -> 291.45455 | N10: =Продажи[[#This Row],[цена за шт в рублях]]/Продажи[[#This Row],[Средняя цена в категории за шт по поставщику]]-1 -> 0.42732377 | O10: =VLOOKUP(Продажи[[#This Row],[id клиента]],клиенты!$A$2:$E$435,5,0) -> 44684 | P10: =Продажи[[#This Row],[дата создания чека]]-Продажи[[#This Row],[Дата регистрации]] -> 692 | Q10: =VLOOKUP(Продажи[[#This Row],[id клиента]],клиенты!$A$2:$G$435,7,0) -> Украина | R10: =IF(COUNTIF($H$2:H10, H10)=1, 1, 0) -> 1 | S10: =VLOOKUP(Продажи[[#This Row],[id клиента]],клиенты!$A$2:$D$435,4,0) -> нет | T10: =VLOOKUP(Продажи[[#This Row],[id клиента]],клиенты!$A$2:$I$435,9,0) -> 22.735113
A11: 10 | B11: 100 | C11: 449 | D11: 2 | E11: 4490 | F11: 45032 | G11: Карусель | H11: 413 | I11: =VLOOKUP(Продажи[[#This Row],[id товара]],Товары[],2,0) -> Йогурт | J11: =AVERAGEIF(Продажи[Категория],Продажи[[#This Row],[Категория]],Продажи[цена за шт в рублях]) -> 263.25424 | K11: =Продажи[[#This Row],[цена за шт в рублях]]/Продажи[[#This Row],[Средняя цена в категории за шт]]-1 -> 0.70557559 | L11: =VLOOKUP(Продажи[[#This Row],[id товара]],Товары[],3,0) -> Ростагроэкспорт | M11: =AVERAGEIFS(Продажи[цена за шт в рублях],Продажи[Категория],Продажи[[#This Row],[Категория]],Продажи[Поставщик],Продажи[[#This Row],[Поставщик]]) -> 257.78261 | N11: =Продажи[[#This Row],[цена за шт в рублях]]/Продажи[[#This Row],[Средняя цена в категории за шт по поставщику]]-1 -> 0.7417777 | O11: =VLOOKUP(Продажи[[#This Row],[id клиента]],клиенты!$A$2:$E$435,5,0) -> 44699 | P11: =Продажи[[#This Row],[дата создания чека]]-Продажи[[#This Row],[Дата регистрации]] -> 333 | Q11: =VLOOKUP(Продажи[[#This Row],[id клиента]],клиенты!$A$2:$G$435,7,0) -> Россия | R11: =IF(COUNTIF($H$2:H11, H11)=1, 1, 0) -> 1 | S11: =VLOOKUP(Продажи[[#This Row],[id клиента]],клиенты!$A$2:$D$435,4,0) -> нет | T11: =VLOOKUP(Продажи[[#This Row],[id клиента]],клиенты!$A$2:$I$435,9,0) -> 17.806982
A12: 11 | B12: 217 | C12: 296 | D12: 2 | E12: 2960 | F12: 45136 | G12: Карусель | H12: 495 | I12: =VLOOKUP(Продажи[[#This Row],[id товара]],Товары[],2,0) -> Мясо | J12: =AVERAGEIF(Продажи[Категория],Продажи[[#This Row],[Категория]],Продажи[цена за шт в рублях]) -> 271.74545 | K12: =Продажи[[#This Row],[цена за шт в рублях]]/Продажи[[#This Row],[Средняя цена в категории за шт]]-1 -> 0.08925465 | L12: =VLOOKUP(Продажи[[#This Row],[id товара]],Товары[],3,0) -> Агрокомплекс | M12: =AVERAGEIFS(Продажи[цена за шт в рублях],Продажи[Категория],Продажи[[#This Row],[Категория]],Продажи[Поставщик],Продажи[[#This Row],[Поставщик]]) -> 311.2 | N12: =Продажи[[#This Row],[цена за шт в рублях]]/Продажи[[#This Row],[Средняя цена в категории за шт по поставщику]]-1 -> -0.048843188 | O12: =VLOOKUP(Продажи[[#This Row],[id клиента]],клиенты!$A$2:$E$435,5,0) -> 44654 | P12: =Продажи[[#This Row],[дата создания чека]]-Продажи[[#This Row],[Дата регистрации]] -> 482 | Q12: =VLOOKUP(Продажи[[#This Row],[id клиента]],клиенты!$A$2:$G$435,7,0) -> Узбекистан | R12: =IF(COUNTIF($H$2:H12, H12)=1, 1, 0) -> 1 | S12: =VLOOKUP(Продажи[[#This Row],[id клиента]],клиенты!$A$2:$D$435,4,0) -> да | T12: =VLOOKUP(Продажи[[#This Row],[id клиента]],клиенты!$A$2:$I$435,9,0) -> 15.835729
A13: 12 | B13: 445 | C13: 109 | D13: 5 | E13: 2725 | F13: 45394 | G13: Мираторг | H13: 353 | I13: =VLOOKUP(Продажи[[#This Row],[id товара]],Товары[],2,0) -> Сахар | J13: =AVERAGEIF(Продажи[Категория],Продажи[[#This Row],[Категория]],Продажи[цена за шт в рублях]) -> 252.76271 | K13: =Продажи[[#This Row],[цена за шт в рублях]]/Продажи[[#This Row],[Средняя цена в категории за шт]]-1 -> -0.56876551 | L13: =VLOOKUP(Продажи[[#This Row],[id товара]],Товары[],3,0) -> Сладов | M13: =AVERAGEIFS(Продажи[цена за шт в рублях],Продажи[Категория],Продажи[[#This Row],[Категория]],Продажи[Поставщик],Продажи[[#This Row],[Поставщик]]) -> 240.26667 | N13: =Продажи[[#This Row],[цена за шт в рублях]]/Продажи[[#This Row],[Средняя цена в категории за шт по поставщику]]-1 -> -0.5463374 | O13: =VLOOKUP(Продажи[[#This Row],[id клиента]],клиенты!$A$2:$E$435,5,0) -> 44656 | P13: =Продажи[[#This Row],[дата создания чека]]-Продажи[[#This Row],[Дата регистрации]] -> 738 | Q13: =VLOOKUP(Продажи[[#This Row],[id клиента]],клиенты!$A$2:$G$435,7,0) -> Таджикистан | R13: =IF(COUNTIF($H$2:H13, H13)=1, 1, 0) -> 1 | S13: =VLOOKUP(Продажи[[#This Row],[id клиента]],клиенты!$A$2:$D$435,4,0) -> да | T13: =VLOOKUP(Продажи[[#This Row],[id клиента]],клиенты!$A$2:$I$435,9,0) -> 24.246407
... A1001: 1000 | B1001: 296 | C1001: 453 | D1001: 1 | E1001: 2265 | F1001: 45265 | G1001: Мосмарт | H1001: 167 | I1001: =VLOOKUP(Продажи[[#This Row],[id товара]],Товары[],2,0) -> Крупа | J1001: =AVERAGEIF(Продажи[Категория],Продажи[[#This Row],[Категория]],Продажи[цена за шт в рублях]) -> 255.11628 | K1001: =Продажи[[#This Row],[цена за шт в рублях]]/Продажи[[#This Row],[Средняя цена в категории за шт]]-1 -> 0.77566089 | L1001: =VLOOKUP(Продажи[[#This Row],[id товара]],Товары[],3,0) -> Мистраль | M1001: =AVERAGEIFS(Продажи[цена за шт в рублях],Продажи[Категория],Продажи[[#This Row],[Категория]],Продажи[Поставщик],Продажи[[#This Row],[Поставщик]]) -> 250.30769 | N1001: =Продажи[[#This Row],[цена за шт в рублях]]/Продажи[[#This Row],[Средняя цена в категории за шт по поставщику]]-1 -> 0.80977259 | O1001: =VLOOKUP(Продажи[[#This Row],[id клиента]],клиенты!$A$2:$E$435,5,0) -> 44563 | P1001: =Продажи[[#This Row],[дата создания чека]]-Продажи[[#This Row],[Дата регистрации]] -> 702 | Q1001: =VLOOKUP(Продажи[[#This Row],[id клиента]],клиенты!$A$2:$G$435,7,0) -> Узбекистан | R1001: =IF(COUNTIF($H$2:H1001, H1001)=1, 1, 0) -> 0 | S1001: =VLOOKUP(Продажи[[#This Row],[id клиента]],клиенты!$A$2:$D$435,4,0) -> да | T1001: =VLOOKUP(Продажи[[#This Row],[id клиента]],клиенты!$A$2:$I$435,9,0) -> 26.119097

Sheet клиенты
A1: id клиента | B1: номер телефона клиента | C1: ФИО | D1: Программа лояльности клиента | E1: Дата регистрации клиента | F1: Коды телефона | G1: Страна клиента | H1: Последнюю дату покупки клиента | I1: Фактический лайфтайм (мес) | J1: ФИО без обращений | K1: ФИО в одинаковом порядке | L1: Имя | M1: Отчество | N1: Фамилия
A2: 315 | B2: +998 469-847-6587 | C2: Фадей Ефимович Калинин | D2: да | E2: 44747 | F2: =LEFT(клиенты!$B2,LEN(клиенты!$B2)-13) -> +998 | G2: =_xlfn.XLOOKUP(клиенты!$F2,'коды стран'!$B$2:$B$7,'коды стран'!$A$2:$A$7,"не найдено",0) -> Узбекистан | H2: =_xlfn.MAXIFS(Продажи[дата создания чека],Продажи[id клиента],A2) -> 45368 | I2: =IFERROR((H2-E2)/30.4375,0) -> 20.402464 | J2: =IF(LEN(C2) - LEN(SUBSTITUTE(C2," ",""))<3,C2,RIGHT(C2,LEN(C2)-FIND(" ",клиенты!$C2,1))) -> Фадей Ефимович Калинин | K2: =IF(OR( RIGHT(MID(C2,FIND(" ",C2)+1,FIND(" ",C2,FIND(" ",C2)+1)-FIND(" ",C2)-1),2)="ич", RIGHT(MID(C2,FIND(" ",C2)+1,FIND(" ",C2,FIND(" ",C2)+1)-FIND(" ",C2)-1),3)="вна", RIGHT(MID(C2,FIND(" ",C2)+1,FIND(" ",C2,FIND(" ",C2)+1)-FIND(" ",C2)-1),3)="чна" ), C2, MID(C2,FIND(" ",C2)+1,FIND(" ",C2,FIND(" ",C2)+1)-FIND(" ",C2)-1)&" "& RIGHT(C2,LEN(C2)-FIND("☐",SUBSTITUTE(C2," ","☐",2)))&" "& LEFT(C2,FIND(" ",C2)-1) ) -> Фадей Ефимович Калинин | L2: =LEFT(клиенты!$K2,FIND(" ",клиенты!$K2,1)-1) -> Фадей | M2: =MID(K2,FIND(" ",клиенты!$K2,1)+1,(FIND(" ",клиенты!$K2,FIND(" ",клиенты!$K2,1)+1)-1)-FIND(" ",клиенты!$K2,1)) -> Ефимович | N2: =RIGHT(K2,LEN(K2)-FIND(" ",клиенты!$K2,FIND(" ",клиенты!$K2,1)+1)) -> Калинин
A3: 253 | B3: +375 796-304-7865 | C3: Вера Георгиевна Некрасова | D3: да | E3: 44750 | F3: =LEFT(клиенты!$B3,LEN(клиенты!$B3)-13) -> +375 | G3: =_xlfn.XLOOKUP(клиенты!$F3,'коды стран'!$B$2:$B$7,'коды стран'!$A$2:$A$7,"не найдено",0) -> Беларусь | H3: =_xlfn.MAXIFS(Продажи[дата создания чека],Продажи[id клиента],A3) -> 45083 | I3: =IFERROR((H3-E3)/30.4375,0) -> 10.940452 | J3: =IF(LEN(C3) - LEN(SUBSTITUTE(C3," ",""))<3,C3,RIGHT(C3,LEN(C3)-FIND(" ",клиенты!$C3,1))) -> Вера Георгиевна Некрасова | K3: =IF(OR( RIGHT(MID(C3,FIND(" ",C3)+1,FIND(" ",C3,FIND(" ",C3)+1)-FIND(" ",C3)-1),2)="ич", RIGHT(MID(C3,FIND(" ",C3)+1,FIND(" ",C3,FIND(" ",C3)+1)-FIND(" ",C3)-1),3)="вна", RIGHT(MID(C3,FIND(" ",C3)+1,FIND(" ",C3,FIND(" ",C3)+1)-FIND(" ",C3)-1),3)="чна" ), C3, MID(C3,FIND(" ",C3)+1,FIND(" ",C3,FIND(" ",C3)+1)-FIND(" ",C3)-1)&" "& RIGHT(C3,LEN(C3)-FIND("☐",SUBSTITUTE(C3," ","☐",2)))&" "& LEFT(C3,FIND(" ",C3)-1) ) -> Вера Георгиевна Некрасова | L3: =LEFT(клиенты!$K3,FIND(" ",клиенты!$K3,1)-1) -> Вера | M3: =MID(K3,FIND(" ",клиенты!$K3,1)+1,(FIND(" ",клиенты!$K3,FIND(" ",клиенты!$K3,1)+1)-1)-FIND(" ",клиенты!$K3,1)) -> Георгиевна | N3: =RIGHT(K3,LEN(K3)-FIND(" ",клиенты!$K3,FIND(" ",клиенты!$K3,1)+1)) -> Некрасова
A4: 12 | B4: +375 682-373-1802 | C4: Никодим Игоревич Бобров | D4: да | E4: 44842 | F4: =LEFT(клиенты!$B4,LEN(клиенты!$B4)-13) -> +375 | G4: =_xlfn.XLOOKUP(клиенты!$F4,'коды стран'!$B$2:$B$7,'коды стран'!$A$2:$A$7,"не найдено",0) -> Беларусь | H4: =_xlfn.MAXIFS(Продажи[дата создания чека],Продажи[id клиента],A4) -> 45363 | I4: =IFERROR((H4-E4)/30.4375,0) -> 17.117043 | J4: =IF(LEN(C4) - LEN(SUBSTITUTE(C4," ",""))<3,C4,RIGHT(C4,LEN(C4)-FIND(" ",клиенты!$C4,1))) -> Никодим Игоревич Бобров | K4: =IF(OR( RIGHT(MID(C4,FIND(" ",C4)+1,FIND(" ",C4,FIND(" ",C4)+1)-FIND(" ",C4)-1),2)="ич", RIGHT(MID(C4,FIND(" ",C4)+1,FIND(" ",C4,FIND(" ",C4)+1)-FIND(" ",C4)-1),3)="вна", RIGHT(MID(C4,FIND(" ",C4)+1,FIND(" ",C4,FIND(" ",C4)+1)-FIND(" ",C4)-1),3)="чна" ), C4, MID(C4,FIND(" ",C4)+1,FIND(" ",C4,FIND(" ",C4)+1)-FIND(" ",C4)-1)&" "& RIGHT(C4,LEN(C4)-FIND("☐",SUBSTITUTE(C4," ","☐",2)))&" "& LEFT(C4,FIND(" ",C4)-1) ) -> Никодим Игоревич Бобров | L4: =LEFT(клиенты!$K4,FIND(" ",клиенты!$K4,1)-1) -> Никодим | M4: =MID(K4,FIND(" ",клиенты!$K4,1)+1,(FIND(" ",клиенты!$K4,FIND(" ",клиенты!$K4,1)+1)-1)-FIND(" ",клиенты!$K4,1)) -> Игоревич | N4: =RIGHT(K4,LEN(K4)-FIND(" ",клиенты!$K4,FIND(" ",клиенты!$K4,1)+1)) -> Бобров
A5: 116 | B5: +7 753-596-5037 | C5: Носкова Вера Федоровна | D5: нет | E5: 44643 | F5: =LEFT(клиенты!$B5,LEN(клиенты!$B5)-13) -> +7 | G5: =_xlfn.XLOOKUP(клиенты!$F5,'коды стран'!$B$2:$B$7,'коды стран'!$A$2:$A$7,"не найдено",0) -> Россия | H5: =_xlfn.MAXIFS(Продажи[дата создания чека],Продажи[id клиента],A5) -> 45286 | I5: =IFERROR((H5-E5)/30.4375,0) -> 21.125257 | J5: =IF(LEN(C5) - LEN(SUBSTITUTE(C5," ",""))<3,C5,RIGHT(C5,LEN(C5)-FIND(" ",клиенты!$C5,1))) -> Носкова Вера Федоровна | K5: =IF(OR( RIGHT(MID(C5,FIND(" ",C5)+1,FIND(" ",C5,FIND(" ",C5)+1)-FIND(" ",C5)-1),2)="ич", RIGHT(MID(C5,FIND(" ",C5)+1,FIND(" ",C5,FIND(" ",C5)+1)-FIND(" ",C5)-1),3)="вна", RIGHT(MID(C5,FIND(" ",C5)+1,FIND(" ",C5,FIND(" ",C5)+1)-FIND(" ",C5)-1),3)="чна" ), C5, MID(C5,FIND(" ",C5)+1,FIND(" ",C5,FIND(" ",C5)+1)-FIND(" ",C5)-1)&" "& RIGHT(C5,LEN(C5)-FIND("☐",SUBSTITUTE(C5," ","☐",2)))&" "& LEFT(C5,FIND(" ",C5)-1) ) -> Вера Федоровна Носкова | L5: =LEFT(клиенты!$K5,FIND(" ",клиенты!$K5,1)-1) -> Вера | M5: =MID(K5,FIND(" ",клиенты!$K5,1)+1,(FIND(" ",клиенты!$K5,FIND(" ",клиенты!$K5,1)+1)-1)-FIND(" ",клиенты!$K5,1)) -> Федоровна | N5: =RIGHT(K5,LEN(K5)-FIND(" ",клиенты!$K5,FIND(" ",клиенты!$K5,1)+1)) -> Носкова
A6: 471 | B6: +380 669-437-2066 | C6: Александра Матвеевна Артемьева | D6: да | E6: 44577 | F6: =LEFT(клиенты!$B6,LEN(клиенты!$B6)-13) -> +380 | G6: =_xlfn.XLOOKUP(клиенты!$F6,'коды стран'!$B$2:$B$7,'коды стран'!$A$2:$A$7,"не найдено",0) -> Украина | H6: =_xlfn.MAXIFS(Продажи[дата создания чека],Продажи[id клиента],A6) -> 45151 | I6: =IFERROR((H6-E6)/30.4375,0) -> 18.858316 | J6: =IF(LEN(C6) - LEN(SUBSTITUTE(C6," ",""))<3,C6,RIGHT(C6,LEN(C6)-FIND(" ",клиенты!$C6,1))) -> Александра Матвеевна Артемьева | K6: =IF(OR( RIGHT(MID(C6,FIND(" ",C6)+1,FIND(" ",C6,FIND(" ",C6)+1)-FIND(" ",C6)-1),2)="ич", RIGHT(MID(C6,FIND(" ",C6)+1,FIND(" ",C6,FIND(" ",C6)+1)-FIND(" ",C6)-1),3)="вна", RIGHT(MID(C6,FIND(" ",C6)+1,FIND(" ",C6,FIND(" ",C6)+1)-FIND(" ",C6)-1),3)="чна" ), C6, MID(C6,FIND(" ",C6)+1,FIND(" ",C6,FIND(" ",C6)+1)-FIND(" ",C6)-1)&" "& RIGHT(C6,LEN(C6)-FIND("☐",SUBSTITUTE(C6," ","☐",2)))&" "& LEFT(C6,FIND(" ",C6)-1) ) -> Александра Матвеевна Артемьева | L6: =LEFT(клиенты!$K6,FIND(" ",клиенты!$K6,1)-1) -> Александра | M6: =MID(K6,FIND(" ",клиенты!$K6,1)+1,(FIND(" ",клиенты!$K6,FIND(" ",клиенты!$K6,1)+1)-1)-FIND(" ",клиенты!$K6,1)) -> Матвеевна | N6: =RIGHT(K6,LEN(K6)-FIND(" ",клиенты!$K6,FIND(" ",клиенты!$K6,1)+1)) -> Артемьева
A7: 374 | B7: +380 622-144-1703 | C7: Калинина Ирина Филипповна | D7: нет | E7: 44582 | F7: =LEFT(клиенты!$B7,LEN(клиенты!$B7)-13) -> +380 | G7: =_xlfn.XLOOKUP(клиенты!$F7,'коды стран'!$B$2:$B$7,'коды стран'!$A$2:$A$7,"не найдено",0) -> Украина | H7: =_xlfn.MAXIFS(Продажи[дата создания чека],Продажи[id клиента],A7) -> 45292 | I7: =IFERROR((H7-E7)/30.4375,0) -> 23.326489 | J7: =IF(LEN(C7) - LEN(SUBSTITUTE(C7," ",""))<3,C7,RIGHT(C7,LEN(C7)-FIND(" ",клиенты!$C7,1))) -> Калинина Ирина Филипповна | K7: =IF(OR( RIGHT(MID(C7,FIND(" ",C7)+1,FIND(" ",C7,FIND(" ",C7)+1)-FIND(" ",C7)-1),2)="ич", RIGHT(MID(C7,FIND(" ",C7)+1,FIND(" ",C7,FIND(" ",C7)+1)-FIND(" ",C7)-1),3)="вна", RIGHT(MID(C7,FIND(" ",C7)+1,FIND(" ",C7,FIND(" ",C7)+1)-FIND(" ",C7)-1),3)="чна" ), C7, MID(C7,FIND(" ",C7)+1,FIND(" ",C7,FIND(" ",C7)+1)-FIND(" ",C7)-1)&" "& RIGHT(C7,LEN(C7)-FIND("☐",SUBSTITUTE(C7," ","☐",2)))&" "& LEFT(C7,FIND(" ",C7)-1) ) -> Ирина Филипповна Калинина | L7: =LEFT(клиенты!$K7,FIND(" ",клиенты!$K7,1)-1) -> Ирина | M7: =MID(K7,FIND(" ",клиенты!$K7,1)+1,(FIND(" ",клиенты!$K7,FIND(" ",клиенты!$K7,1)+1)-1)-FIND(" ",клиенты!$K7,1)) -> Филипповна | N7: =RIGHT(K7,LEN(K7)-FIND(" ",клиенты!$K7,FIND(" ",клиенты!$K7,1)+1)) -> Калинина
A8: 477 | B8: +998 591-865-8342 | C8: Зоя Кирилловна Брагина | D8: да | E8: 44738 | F8: =LEFT(клиенты!$B8,LEN(клиенты!$B8)-13) -> +998 | G8: =_xlfn.XLOOKUP(клиенты!$F8,'коды стран'!$B$2:$B$7,'коды стран'!$A$2:$A$7,"не найдено",0) -> Узбекистан | H8: =_xlfn.MAXIFS(Продажи[дата создания чека],Продажи[id клиента],A8) -> 45349 | I8: =IFERROR((H8-E8)/30.4375,0) -> 20.073922 | J8: =IF(LEN(C8) - LEN(SUBSTITUTE(C8," ",""))<3,C8,RIGHT(C8,LEN(C8)-FIND(" ",клиенты!$C8,1))) -> Зоя Кирилловна Брагина | K8: =IF(OR( RIGHT(MID(C8,FIND(" ",C8)+1,FIND(" ",C8,FIND(" ",C8)+1)-FIND(" ",C8)-1),2)="ич", RIGHT(MID(C8,FIND(" ",C8)+1,FIND(" ",C8,FIND(" ",C8)+1)-FIND(" ",C8)-1),3)="вна", RIGHT(MID(C8,FIND(" ",C8)+1,FIND(" ",C8,FIND(" ",C8)+1)-FIND(" ",C8)-1),3)="чна" ), C8, MID(C8,FIND(" ",C8)+1,FIND(" ",C8,FIND(" ",C8)+1)-FIND(" ",C8)-1)&" "& RIGHT(C8,LEN(C8)-FIND("☐",SUBSTITUTE(C8," ","☐",2)))&" "& LEFT(C8,FIND(" ",C8)-1) ) -> Зоя Кирилловна Брагина | L8: =LEFT(клиенты!$K8,FIND(" ",клиенты!$K8,1)-1) -> Зоя | M8: =MID(K8,FIND(" ",клиенты!$K8,1)+1,(FIND(" ",клиенты!$K8,FIND(" ",клиенты!$K8,1)+1)-1)-FIND(" ",клиенты!$K8,1)) -> Кирилловна | N8: =RIGHT(K8,LEN(K8)-FIND(" ",клиенты!$K8,FIND(" ",клиенты!$K8,1)+1)) -> Брагина
A9: 335 | B9: +998 353-736-8172 | C9: Осипов Светозар Ефремович | D9: нет | E9: 44619 | F9: =LEFT(клиенты!$B9,LEN(клиенты!$B9)-13) -> +998 | G9: =_xlfn.XLOOKUP(клиенты!$F9,'коды стран'!$B$2:$B$7,'коды стран'!$A$2:$A$7,"не найдено",0) -> Узбекистан | H9: =_xlfn.MAXIFS(Продажи[дата создания чека],Продажи[id клиента],A9) -> 45327 | I9: =IFERROR((H9-E9)/30.4375,0) -> 23.26078 | J9: =IF(LEN(C9) - LEN(SUBSTITUTE(C9," ",""))<3,C9,RIGHT(C9,LEN(C9)-FIND(" ",клиенты!$C9,1))) -> Осипов Светозар Ефремович | K9: =IF(OR( RIGHT(MID(C9,FIND(" ",C9)+1,FIND(" ",C9,FIND(" ",C9)+1)-FIND(" ",C9)-1),2)="ич", RIGHT(MID(C9,FIND(" ",C9)+1,FIND(" ",C9,FIND(" ",C9)+1)-FIND(" ",C9)-1),3)="вна", RIGHT(MID(C9,FIND(" ",C9)+1,FIND(" ",C9,FIND(" ",C9)+1)-FIND(" ",C9)-1),3)="чна" ), C9, MID(C9,FIND(" ",C9)+1,FIND(" ",C9,FIND(" ",C9)+1)-FIND(" ",C9)-1)&" "& RIGHT(C9,LEN(C9)-FIND("☐",SUBSTITUTE(C9," ","☐",2)))&" "& LEFT(C9,FIND(" ",C9)-1) ) -> Светозар Ефремович Осипов | L9: =LEFT(клиенты!$K9,FIND(" ",клиенты!$K9,1)-1) -> Светозар | M9: =MID(K9,FIND(" ",клиенты!$K9,1)+1,(FIND(" ",клиенты!$K9,FIND(" ",клиенты!$K9,1)+1)-1)-FIND(" ",клиенты!$K9,1)) -> Ефремович | N9: =RIGHT(K9,LEN(K9)-FIND(" ",клиенты!$K9,FIND(" ",клиенты!$K9,1)+1)) -> Осипов
A10: 350 | B10: +380 545-746-8707 | C10: Любовь Георгиевна Мамонтова | D10: нет | E10: 44684 | F10: =LEFT(клиенты!$B10,LEN(клиенты!$B10)-13) -> +380 | G10: =_xlfn.XLOOKUP(клиенты!$F10,'коды стран'!$B$2:$B$7,'коды стран'!$A$2:$A$7,"не найдено",0) -> Украина | H10: =_xlfn.MAXIFS(Продажи[дата создания чека],Продажи[id клиента],A10) -> 45376 | I10: =IFERROR((H10-E10)/30.4375,0) -> 22.735113 | J10: =IF(LEN(C10) - LEN(SUBSTITUTE(C10," ",""))<3,C10,RIGHT(C10,LEN(C10)-FIND(" ",клиенты!$C10,1))) -> Любовь Георгиевна Мамонтова | K10: =IF(OR( RIGHT(MID(C10,FIND(" ",C10)+1,FIND(" ",C10,FIND(" ",C10)+1)-FIND(" ",C10)-1),2)="ич", RIGHT(MID(C10,FIND(" ",C10)+1,FIND(" ",C10,FIND(" ",C10)+1)-FIND(" ",C10)-1),3)="вна", RIGHT(MID(C10,FIND(" ",C10)+1,FIND(" ",C10,FIND(" ",C10)+1)-FIND(" ",C10)-1),3)="чна" ), C10, MID(C10,FIND(" ",C10)+1,FIND(" ",C10,FIND(" ",C10)+1)-FIND(" ",C10)-1)&" "& RIGHT(C10,LEN(C10)-FIND("☐",SUBSTITUTE(C10," ","☐",2)))&" "& LEFT(C10,FIND(" ",C10)-1) ) -> Любовь Георгиевна Мамонтова | L10: =LEFT(клиенты!$K10,FIND(" ",клиенты!$K10,1)-1) -> Любовь | M10: =MID(K10,FIND(" ",клиенты!$K10,1)+1,(FIND(" ",клиенты!$K10,FIND(" ",клиенты!$K10,1)+1)-1)-FIND(" ",клиенты!$K10,1)) -> Георгиевна | N10: =RIGHT(K10,LEN(K10)-FIND(" ",клиенты!$K10,FIND(" ",клиенты!$K10,1)+1)) -> Мамонтова
A11: 413 | B11: +7 063-931-5918 | C11: Август Вячеславович Брагин | D11: нет | E11: 44699 | F11: =LEFT(клиенты!$B11,LEN(клиенты!$B11)-13) -> +7 | G11: =_xlfn.XLOOKUP(клиенты!$F11,'коды стран'!$B$2:$B$7,'коды стран'!$A$2:$A$7,"не найдено",0) -> Россия | H11: =_xlfn.MAXIFS(Продажи[дата создания чека],Продажи[id клиента],A11) -> 45241 | I11: =IFERROR((H11-E11)/30.4375,0) -> 17.806982 | J11: =IF(LEN(C11) - LEN(SUBSTITUTE(C11," ",""))<3,C11,RIGHT(C11,LEN(C11)-FIND(" ",клиенты!$C11,1))) -> Август Вячеславович Брагин | K11: =IF(OR( RIGHT(MID(C11,FIND(" ",C11)+1,FIND(" ",C11,FIND(" ",C11)+1)-FIND(" ",C11)-1),2)="ич", RIGHT(MID(C11,FIND(" ",C11)+1,FIND(" ",C11,FIND(" ",C11)+1)-FIND(" ",C11)-1),3)="вна", RIGHT(MID(C11,FIND(" ",C11)+1,FIND(" ",C11,FIND(" ",C11)+1)-FIND(" ",C11)-1),3)="чна" ), C11, MID(C11,FIND(" ",C11)+1,FIND(" ",C11,FIND(" ",C11)+1)-FIND(" ",C11)-1)&" "& RIGHT(C11,LEN(C11)-FIND("☐",SUBSTITUTE(C11," ","☐",2)))&" "& LEFT(C11,FIND(" ",C11)-1) ) -> Август Вячеславович Брагин | L11: =LEFT(клиенты!$K11,FIND(" ",клиенты!$K11,1)-1) -> Август | M11: =MID(K11,FIND(" ",клиенты!$K11,1)+1,(FIND(" ",клиенты!$K11,FIND(" ",клиенты!$K11,1)+1)-1)-FIND(" ",клиенты!$K11,1)) -> Вячеславович | N11: =RIGHT(K11,LEN(K11)-FIND(" ",клиенты!$K11,FIND(" ",клиенты!$K11,1)+1)) -> Брагин
A12: 495 | B12: +998 006-788-9211 | C12: Мефодий Филиппович Воробьев | D12: да | E12: 44654 | F12: =LEFT(клиенты!$B12,LEN(клиенты!$B12)-13) -> +998 | G12: =_xlfn.XLOOKUP(клиенты!$F12,'коды стран'!$B$2:$B$7,'коды стран'!$A$2:$A$7,"не найдено",0) -> Узбекистан | H12: =_xlfn.MAXIFS(Продажи[дата создания чека],Продажи[id клиента],A12) -> 45136 | I12: =IFERROR((H12-E12)/30.4375,0) -> 15.835729 | J12: =IF(LEN(C12) - LEN(SUBSTITUTE(C12," ",""))<3,C12,RIGHT(C12,LEN(C12)-FIND(" ",клиенты!$C12,1))) -> Мефодий Филиппович Воробьев | K12: =IF(OR( RIGHT(MID(C12,FIND(" ",C12)+1,FIND(" ",C12,FIND(" ",C12)+1)-FIND(" ",C12)-1),2)="ич", RIGHT(MID(C12,FIND(" ",C12)+1,FIND(" ",C12,FIND(" ",C12)+1)-FIND(" ",C12)-1),3)="вна", RIGHT(MID(C12,FIND(" ",C12)+1,FIND(" ",C12,FIND(" ",C12)+1)-FIND(" ",C12)-1),3)="чна" ), C12, MID(C12,FIND(" ",C12)+1,FIND(" ",C12,FIND(" ",C12)+1)-FIND(" ",C12)-1)&" "& RIGHT(C12,LEN(C12)-FIND("☐",SUBSTITUTE(C12," ","☐",2)))&" "& LEFT(C12,FIND(" ",C12)-1) ) -> Мефодий Филиппович Воробьев | L12: =LEFT(клиенты!$K12,FIND(" ",клиенты!$K12,1)-1) -> Мефодий | M12: =MID(K12,FIND(" ",клиенты!$K12,1)+1,(FIND(" ",клиенты!$K12,FIND(" ",клиенты!$K12,1)+1)-1)-FIND(" ",клиенты!$K12,1)) -> Филиппович | N12: =RIGHT(K12,LEN(K12)-FIND(" ",клиенты!$K12,FIND(" ",клиенты!$K12,1)+1)) -> Воробьев
A13: 353 | B13: +992 863-895-4307 | C13: Гурьев Влас Юлианович | D13: да | E13: 44656 | F13: =LEFT(клиенты!$B13,LEN(клиенты!$B13)-13) -> +992 | G13: =_xlfn.XLOOKUP(клиенты!$F13,'коды стран'!$B$2:$B$7,'коды стран'!$A$2:$A$7,"не найдено",0) -> Таджикистан | H13: =_xlfn.MAXIFS(Продажи[дата создания чека],Продажи[id клиента],A13) -> 45394 | I13: =IFERROR((H13-E13)/30.4375,0) -> 24.246407 | J13: =IF(LEN(C13) - LEN(SUBSTITUTE(C13," ",""))<3,C13,RIGHT(C13,LEN(C13)-FIND(" ",клиенты!$C13,1))) -> Гурьев Влас Юлианович | K13: =IF(OR( RIGHT(MID(C13,FIND(" ",C13)+1,FIND(" ",C13,FIND(" ",C13)+1)-FIND(" ",C13)-1),2)="ич", RIGHT(MID(C13,FIND(" ",C13)+1,FIND(" ",C13,FIND(" ",C13)+1)-FIND(" ",C13)-1),3)="вна", RIGHT(MID(C13,FIND(" ",C13)+1,FIND(" ",C13,FIND(" ",C13)+1)-FIND(" ",C13)-1),3)="чна" ), C13, MID(C13,FIND(" ",C13)+1,FIND(" ",C13,FIND(" ",C13)+1)-FIND(" ",C13)-1)&" "& RIGHT(C13,LEN(C13)-FIND("☐",SUBSTITUTE(C13," ","☐",2)))&" "& LEFT(C13,FIND(" ",C13)-1) ) -> Влас Юлианович Гурьев | L13: =LEFT(клиенты!$K13,FIND(" ",клиенты!$K13,1)-1) -> Влас | M13: =MID(K13,FIND(" ",клиенты!$K13,1)+1,(FIND(" ",клиенты!$K13,FIND(" ",клиенты!$K13,1)+1)-1)-FIND(" ",клиенты!$K13,1)) -> Юлианович | N13: =RIGHT(K13,LEN(K13)-FIND(" ",клиенты!$K13,FIND(" ",клиенты!$K13,1)+1)) -> Гурьев
... A25: 39 | B25: +375 226-887-4565 | C25: Бирюков Олимпий Иосифович | D25: да | E25: 44653 | F25: =LEFT(клиенты!$B25,LEN(клиенты!$B25)-13) -> +375 | G25: =_xlfn.XLOOKUP(клиенты!$F25,'коды стран'!$B$2:$B$7,'коды стран'!$A$2:$A$7,"не найдено",0) -> Беларусь | H25: =_xlfn.MAXIFS(Продажи[дата создания чека],Продажи[id клиента],A25) -> 45003 | I25: =IFERROR((H25-E25)/30.4375,0) -> 11.498973 | J25: =IF(LEN(C25) - LEN(SUBSTITUTE(C25," ",""))<3,C25,RIGHT(C25,LEN(C25)-FIND(" ",клиенты!$C25,1))) -> Бирюков Олимпий Иосифович | K25: =IF(OR( RIGHT(MID(C25,FIND(" ",C25)+1,FIND(" ",C25,FIND(" ",C25)+1)-FIND(" ",C25)-1),2)="ич", RIGHT(MID(C25,FIND(" ",C25)+1,FIND(" ",C25,FIND(" ",C25)+1)-FIND(" ",C25)-1),3)="вна", RIGHT(MID(C25,FIND(" ",C25)+1,FIND(" ",C25,FIND(" ",C25)+1)-FIND(" ",C25)-1),3)="чна" ), C25, MID(C25,FIND(" ",C25)+1,FIND(" ",C25,FIND(" ",C25)+1)-FIND(" ",C25)-1)&" "& RIGHT(C25,LEN(C25)-FIND("☐",SUBSTITUTE(C25," ","☐",2)))&" "& LEFT(C25,FIND(" ",C25)-1) ) -> Олимпий Иосифович Бирюков | L25: =LEFT(клиенты!$K25,FIND(" ",клиенты!$K25,1)-1) -> Олимпий | M25: =MID(K25,FIND(" ",клиенты!$K25,1)+1,(FIND(" ",клиенты!$K25,FIND(" ",клиенты!$K25,1)+1)-1)-FIND(" ",клиенты!$K25,1)) -> Иосифович | N25: =RIGHT(K25,LEN(K25)-FIND(" ",клиенты!$K25,FIND(" ",клиенты!$K25,1)+1)) -> Бирюков
A26: 303 | B26: +998 222-956-9780 | C26: Чеслав Виленович Шестаков | D26: нет | E26: 44689 | F26: =LEFT(клиенты!$B26,LEN(клиенты!$B26)-13) -> +998 | G26: =_xlfn.XLOOKUP(клиенты!$F26,'коды стран'!$B$2:$B$7,'коды стран'!$A$2:$A$7,"не найдено",0) -> Узбекистан | H26: =_xlfn.MAXIFS(Продажи[дата создания чека],Продажи[id клиента],A26) -> 45326 | I26: =IFERROR((H26-E26)/30.4375,0) -> 20.928131 | J26: =IF(LEN(C26) - LEN(SUBSTITUTE(C26," ",""))<3,C26,RIGHT(C26,LEN(C26)-FIND(" ",клиенты!$C26,1))) -> Чеслав Виленович Шестаков | K26: =IF(OR( RIGHT(MID(C26,FIND(" ",C26)+1,FIND(" ",C26,FIND(" ",C26)+1)-FIND(" ",C26)-1),2)="ич", RIGHT(MID(C26,FIND(" ",C26)+1,FIND(" ",C26,FIND(" ",C26)+1)-FIND(" ",C26)-1),3)="вна", RIGHT(MID(C26,FIND(" ",C26)+1,FIND(" ",C26,FIND(" ",C26)+1)-FIND(" ",C26)-1),3)="чна" ), C26, MID(C26,FIND(" ",C26)+1,FIND(" ",C26,FIND(" ",C26)+1)-FIND(" ",C26)-1)&" "& RIGHT(C26,LEN(C26)-FIND("☐",SUBSTITUTE(C26," ","☐",2)))&" "& LEFT(C26,FIND(" ",C26)-1) ) -> Чеслав Виленович Шестаков | L26: =LEFT(клиенты!$K26,FIND(" ",клиенты!$K26,1)-1) -> Чеслав | M26: =MID(K26,FIND(" ",клиенты!$K26,1)+1,(FIND(" ",клиенты!$K26,FIND(" ",клиенты!$K26,1)+1)-1)-FIND(" ",клиенты!$K26,1)) -> Виленович | N26: =RIGHT(K26,LEN(K26)-FIND(" ",клиенты!$K26,FIND(" ",клиенты!$K26,1)+1)) -> Шестаков | Q26: Преимущественное число клиентов были зарегистрированы от 36 до 37 месяцев назад. Наименьшее число клиентов зарегистрированы более 41 месяца назад.
A27: 422 | B27: +380 633-205-1404 | C27: Виноградов Карл Алексеевич | D27: нет | E27: 44784 | F27: =LEFT(клиенты!$B27,LEN(клиенты!$B27)-13) -> +380 | G27: =_xlfn.XLOOKUP(клиенты!$F27,'коды стран'!$B$2:$B$7,'коды стран'!$A$2:$A$7,"не найдено",0) -> Украина | H27: =_xlfn.MAXIFS(Продажи[дата создания чека],Продажи[id клиента],A27) -> 45174 | I27: =IFERROR((H27-E27)/30.4375,0) -> 12.813142 | J27: =IF(LEN(C27) - LEN(SUBSTITUTE(C27," ",""))<3,C27,RIGHT(C27,LEN(C27)-FIND(" ",клиенты!$C27,1))) -> Виноградов Карл Алексеевич | K27: =IF(OR( RIGHT(MID(C27,FIND(" ",C27)+1,FIND(" ",C27,FIND(" ",C27)+1)-FIND(" ",C27)-1),2)="ич", RIGHT(MID(C27,FIND(" ",C27)+1,FIND(" ",C27,FIND(" ",C27)+1)-FIND(" ",C27)-1),3)="вна", RIGHT(MID(C27,FIND(" ",C27)+1,FIND(" ",C27,FIND(" ",C27)+1)-FIND(" ",C27)-1),3)="чна" ), C27, MID(C27,FIND(" ",C27)+1,FIND(" ",C27,FIND(" ",C27)+1)-FIND(" ",C27)-1)&" "& RIGHT(C27,LEN(C27)-FIND("☐",SUBSTITUTE(C27," ","☐",2)))&" "& LEFT(C27,FIND(" ",C27)-1) ) -> Карл Алексеевич Виноградов | L27: =LEFT(клиенты!$K27,FIND(" ",клиенты!$K27,1)-1) -> Карл | M27: =MID(K27,FIND(" ",клиенты!$K27,1)+1,(FIND(" ",клиенты!$K27,FIND(" ",клиенты!$K27,1)+1)-1)-FIND(" ",клиенты!$K27,1)) -> Алексеевич | N27: =RIGHT(K27,LEN(K27)-FIND(" ",клиенты!$K27,FIND(" ",клиенты!$K27,1)+1)) -> Виноградов
A28: 24 | B28: +998 525-413-6836 | C28: Кудрявцева Ульяна Филипповна | D28: да | E28: 44609 | F28: =LEFT(клиенты!$B28,LEN(клиенты!$B28)-13) -> +998 | G28: =_xlfn.XLOOKUP(клиенты!$F28,'коды стран'!$B$2:$B$7,'коды стран'!$A$2:$A$7,"не найдено",0) -> Узбекистан | H28: =_xlfn.MAXIFS(Продажи[дата создания чека],Продажи[id клиента],A28) -> 45300 | I28: =IFERROR((H28-E28)/30.4375,0) -> 22.702259 | J28: =IF(LEN(C28) - LEN(SUBSTITUTE(C28," ",""))<3,C28,RIGHT(C28,LEN(C28)-FIND(" ",клиенты!$C28,1))) -> Кудрявцева Ульяна Филипповна | K28: =IF(OR( RIGHT(MID(C28,FIND(" ",C28)+1,FIND(" ",C28,FIND(" ",C28)+1)-FIND(" ",C28)-1),2)="ич", RIGHT(MID(C28,FIND(" ",C28)+1,FIND(" ",C28,FIND(" ",C28)+1)-FIND(" ",C28)-1),3)="вна", RIGHT(MID(C28,FIND(" ",C28)+1,FIND(" ",C28,FIND(" ",C28)+1)-FIND(" ",C28)-1),3)="чна" ), C28, MID(C28,FIND(" ",C28)+1,FIND(" ",C28,FIND(" ",C28)+1)-FIND(" ",C28)-1)&" "& RIGHT(C28,LEN(C28)-FIND("☐",SUBSTITUTE(C28," ","☐",2)))&" "& LEFT(C28,FIND(" ",C28)-1) ) -> Ульяна Филипповна Кудрявцева | L28: =LEFT(клиенты!$K28,FIND(" ",клиенты!$K28,1)-1) -> Ульяна | M28: =MID(K28,FIND(" ",клиенты!$K28,1)+1,(FIND(" ",клиенты!$K28,FIND(" ",клиенты!$K28,1)+1)-1)-FIND(" ",клиенты!$K28,1)) -> Филипповна | N28: =RIGHT(K28,LEN(K28)-FIND(" ",клиенты!$K28,FIND(" ",клиенты!$K28,1)+1)) -> Кудрявцева
A29: 112 | B29: +7 592-570-4871 | C29: Майя Вадимовна Рябова | D29: нет | E29: 44652 | F29: =LEFT(клиенты!$B29,LEN(клиенты!$B29)-13) -> +7 | G29: =_xlfn.XLOOKUP(клиенты!$F29,'коды стран'!$B$2:$B$7,'коды стран'!$A$2:$A$7,"не найдено",0) -> Россия | H29: =_xlfn.MAXIFS(Продажи[дата создания чека],Продажи[id клиента],A29) -> 45368 | I29: =IFERROR((H29-E29)/30.4375,0) -> 23.523614 | J29: =IF(LEN(C29) - LEN(SUBSTITUTE(C29," ",""))<3,C29,RIGHT(C29,LEN(C29)-FIND(" ",клиенты!$C29,1))) -> Майя Вадимовна Рябова | K29: =IF(OR( RIGHT(MID(C29,FIND(" ",C29)+1,FIND(" ",C29,FIND(" ",C29)+1)-FIND(" ",C29)-1),2)="ич", RIGHT(MID(C29,FIND(" ",C29)+1,FIND(" ",C29,FIND(" ",C29)+1)-FIND(" ",C29)-1),3)="вна", RIGHT(MID(C29,FIND(" ",C29)+1,FIND(" ",C29,FIND(" ",C29)+1)-FIND(" ",C29)-1),3)="чна" ), C29, MID(C29,FIND(" ",C29)+1,FIND(" ",C29,FIND(" ",C29)+1)-FIND(" ",C29)-1)&" "& RIGHT(C29,LEN(C29)-FIND("☐",SUBSTITUTE(C29," ","☐",2)))&" "& LEFT(C29,FIND(" ",C29)-1) ) -> Майя Вадимовна Рябова | L29: =LEFT(клиенты!$K29,FIND(" ",клиенты!$K29,1)-1) -> Майя | M29: =MID(K29,FIND(" ",клиенты!$K29,1)+1,(FIND(" ",клиенты!$K29,FIND(" ",клиенты!$K29,1)+1)-1)-FIND(" ",клиенты!$K29,1)) -> Вадимовна | N29: =RIGHT(K29,LEN(K29)-FIND(" ",клиенты!$K29,FIND(" ",клиенты!$K29,1)+1)) -> Рябова
A30: 451 | B30: +7 321-005-5110 | C30: Лукия Ефимовна Тимофеева | D30: да | E30: 44584 | F30: =LEFT(клиенты!$B30,LEN(клиенты!$B30)-13) -> +7 | G30: =_xlfn.XLOOKUP(клиенты!$F30,'коды стран'!$B$2:$B$7,'коды стран'!$A$2:$A$7,"не найдено",0) -> Россия | H30: =_xlfn.MAXIFS(Продажи[дата создания чека],Продажи[id клиента],A30) -> 45040 | I30: =IFERROR((H30-E30)/30.4375,0) -> 14.98152 | J30: =IF(LEN(C30) - LEN(SUBSTITUTE(C30," ",""))<3,C30,RIGHT(C30,LEN(C30)-FIND(" ",клиенты!$C30,1))) -> Лукия Ефимовна Тимофеева | K30: =IF(OR( RIGHT(MID(C30,FIND(" ",C30)+1,FIND(" ",C30,FIND(" ",C30)+1)-FIND(" ",C30)-1),2)="ич", RIGHT(MID(C30,FIND(" ",C30)+1,FIND(" ",C30,FIND(" ",C30)+1)-FIND(" ",C30)-1),3)="вна", RIGHT(MID(C30,FIND(" ",C30)+1,FIND(" ",C30,FIND(" ",C30)+1)-FIND(" ",C30)-1),3)="чна" ), C30, MID(C30,FIND(" ",C30)+1,FIND(" ",C30,FIND(" ",C30)+1)-FIND(" ",C30)-1)&" "& RIGHT(C30,LEN(C30)-FIND("☐",SUBSTITUTE(C30," ","☐",2)))&" "& LEFT(C30,FIND(" ",C30)-1) ) -> Лукия Ефимовна Тимофеева | L30: =LEFT(клиенты!$K30,FIND(" ",клиенты!$K30,1)-1) -> Лукия | M30: =MID(K30,FIND(" ",клиенты!$K30,1)+1,(FIND(" ",клиенты!$K30,FIND(" ",клиенты!$K30,1)+1)-1)-FIND(" ",клиенты!$K30,1)) -> Ефимовна | N30: =RIGHT(K30,LEN(K30)-FIND(" ",клиенты!$K30,FIND(" ",клиенты!$K30,1)+1)) -> Тимофеева
A31: 131 | B31: +7 899-265-0963 | C31: Полина Николаевна Евдокимова | D31: да | E31: 44693 | F31: =LEFT(клиенты!$B31,LEN(клиенты!$B31)-13) -> +7 | G31: =_xlfn.XLOOKUP(клиенты!$F31,'коды стран'!$B$2:$B$7,'коды стран'!$A$2:$A$7,"не найдено",0) -> Россия | H31: =_xlfn.MAXIFS(Продажи[дата создания чека],Продажи[id клиента],A31) -> 45414 | I31: =IFERROR((H31-E31)/30.4375,0) -> 23.687885 | J31: =IF(LEN(C31) - LEN(SUBSTITUTE(C31," ",""))<3,C31,RIGHT(C31,LEN(C31)-FIND(" ",клиенты!$C31,1))) -> Полина Николаевна Евдокимова | K31: =IF(OR( RIGHT(MID(C31,FIND(" ",C31)+1,FIND(" ",C31,FIND(" ",C31)+1)-FIND(" ",C31)-1),2)="ич", RIGHT(MID(C31,FIND(" ",C31)+1,FIND(" ",C31,FIND(" ",C31)+1)-FIND(" ",C31)-1),3)="вна", RIGHT(MID(C31,FIND(" ",C31)+1,FIND(" ",C31,FIND(" ",C31)+1)-FIND(" ",C31)-1),3)="чна" ), C31, MID(C31,FIND(" ",C31)+1,FIND(" ",C31,FIND(" ",C31)+1)-FIND(" ",C31)-1)&" "& RIGHT(C31,LEN(C31)-FIND("☐",SUBSTITUTE(C31," ","☐",2)))&" "& LEFT(C31,FIND(" ",C31)-1) ) -> Полина Николаевна Евдокимова | L31: =LEFT(клиенты!$K31,FIND(" ",клиенты!$K31,1)-1) -> Полина | M31: =MID(K31,FIND(" ",клиенты!$K31,1)+1,(FIND(" ",клиенты!$K31,FIND(" ",клиенты!$K31,1)+1)-1)-FIND(" ",клиенты!$K31,1)) -> Николаевна | N31: =RIGHT(K31,LEN(K31)-FIND(" ",клиенты!$K31,FIND(" ",клиенты!$K31,1)+1)) -> Евдокимова
A32: 160 | B32: +998 084-412-0746 | C32: Элеонора Ивановна Королева | D32: да | E32: 44649 | F32: =LEFT(клиенты!$B32,LEN(клиенты!$B32)-13) -> +998 | G32: =_xlfn.XLOOKUP(клиенты!$F32,'коды стран'!$B$2:$B$7,'коды стран'!$A$2:$A$7,"не найдено",0) -> Узбекистан | H32: =_xlfn.MAXIFS(Продажи[дата создания чека],Продажи[id клиента],A32) -> 45125 | I32: =IFERROR((H32-E32)/30.4375,0) -> 15.638604 | J32: =IF(LEN(C32) - LEN(SUBSTITUTE(C32," ",""))<3,C32,RIGHT(C32,LEN(C32)-FIND(" ",клиенты!$C32,1))) -> Элеонора Ивановна Королева | K32: =IF(OR( RIGHT(MID(C32,FIND(" ",C32)+1,FIND(" ",C32,FIND(" ",C32)+1)-FIND(" ",C32)-1),2)="ич", RIGHT(MID(C32,FIND(" ",C32)+1,FIND(" ",C32,FIND(" ",C32)+1)-FIND(" ",C32)-1),3)="вна", RIGHT(MID(C32,FIND(" ",C32)+1,FIND(" ",C32,FIND(" ",C32)+1)-FIND(" ",C32)-1),3)="чна" ), C32, MID(C32,FIND(" ",C32)+1,FIND(" ",C32,FIND(" ",C32)+1)-FIND(" ",C32)-1)&" "& RIGHT(C32,LEN(C32)-FIND("☐",SUBSTITUTE(C32," ","☐",2)))&" "& LEFT(C32,FIND(" ",C32)-1) ) -> Элеонора Ивановна Королева | L32: =LEFT(клиенты!$K32,FIND(" ",клиенты!$K32,1)-1) -> Элеонора | M32: =MID(K32,FIND(" ",клиенты!$K32,1)+1,(FIND(" ",клиенты!$K32,FIND(" ",клиенты!$K32,1)+1)-1)-FIND(" ",клиенты!$K32,1)) -> Ивановна | N32: =RIGHT(K32,LEN(K32)-FIND(" ",клиенты!$K32,FIND(" ",клиенты!$K32,1)+1)) -> Королева
A33: 408 | B33: +7 630-977-5834 | C33: Юлия Вячеславовна Журавлева | D33: нет | E33: 44857 | F33: =LEFT(клиенты!$B33,LEN(клиенты!$B33)-13) -> +7 | G33: =_xlfn.XLOOKUP(клиенты!$F33,'коды стран'!$B$2:$B$7,'коды стран'!$A$2:$A$7,"не найдено",0) -> Россия | H33: =_xlfn.MAXIFS(Продажи[дата создания чека],Продажи[id клиента],A33) -> 45355 | I33: =IFERROR((H33-E33)/30.4375,0) -> 16.361396 | J33: =IF(LEN(C33) - LEN(SUBSTITUTE(C33," ",""))<3,C33,RIGHT(C33,LEN(C33)-FIND(" ",клиенты!$C33,1))) -> Юлия Вячеславовна Журавлева | K33: =IF(OR( RIGHT(MID(C33,FIND(" ",C33)+1,FIND(" ",C33,FIND(" ",C33)+1)-FIND(" ",C33)-1),2)="ич", RIGHT(MID(C33,FIND(" ",C33)+1,FIND(" ",C33,FIND(" ",C33)+1)-FIND(" ",C33)-1),3)="вна", RIGHT(MID(C33,FIND(" ",C33)+1,FIND(" ",C33,FIND(" ",C33)+1)-FIND(" ",C33)-1),3)="чна" ), C33, MID(C33,FIND(" ",C33)+1,FIND(" ",C33,FIND(" ",C33)+1)-FIND(" ",C33)-1)&" "& RIGHT(C33,LEN(C33)-FIND("☐",SUBSTITUTE(C33," ","☐",2)))&" "& LEFT(C33,FIND(" ",C33)-1) ) -> Юлия Вячеславовна Журавлева | L33: =LEFT(клиенты!$K33,FIND(" ",клиенты!$K33,1)-1) -> Юлия | M33: =MID(K33,FIND(" ",клиенты!$K33,1)+1,(FIND(" ",клиенты!$K33,FIND(" ",клиенты!$K33,1)+1)-1)-FIND(" ",клиенты!$K33,1)) -> Вячеславовна | N33: =RIGHT(K33,LEN(K33)-FIND(" ",клиенты!$K33,FIND(" ",клиенты!$K33,1)+1)) -> Журавлева
A34: 324 | B34: +998 752-893-8536 | C34: Алексеев Касьян Ефимович | D34: нет | E34: 44761 | F34: =LEFT(клиенты!$B34,LEN(клиенты!$B34)-13) -> +998 | G34: =_xlfn.XLOOKUP(клиенты!$F34,'коды стран'!$B$2:$B$7,'коды стран'!$A$2:$A$7,"не найдено",0) -> Узбекистан | H34: =_xlfn.MAXIFS(Продажи[дата создания чека],Продажи[id клиента],A34) -> 45405 | I34: =IFERROR((H34-E34)/30.4375,0) -> 21.158111 | J34: =IF(LEN(C34) - LEN(SUBSTITUTE(C34," ",""))<3,C34,RIGHT(C34,LEN(C34)-FIND(" ",клиенты!$C34,1))) -> Алексеев Касьян Ефимович | K34: =IF(OR( RIGHT(MID(C34,FIND(" ",C34)+1,FIND(" ",C34,FIND(" ",C34)+1)-FIND(" ",C34)-1),2)="ич", RIGHT(MID(C34,FIND(" ",C34)+1,FIND(" ",C34,FIND(" ",C34)+1)-FIND(" ",C34)-1),3)="вна", RIGHT(MID(C34,FIND(" ",C34)+1,FIND(" ",C34,FIND(" ",C34)+1)-FIND(" ",C34)-1),3)="чна" ), C34, MID(C34,FIND(" ",C34)+1,FIND(" ",C34,FIND(" ",C34)+1)-FIND(" ",C34)-1)&" "& RIGHT(C34,LEN(C34)-FIND("☐",SUBSTITUTE(C34," ","☐",2)))&" "& LEFT(C34,FIND(" ",C34)-1) ) -> Касьян Ефимович Алексеев | L34: =LEFT(клиенты!$K34,FIND(" ",клиенты!$K34,1)-1) -> Касьян | M34: =MID(K34,FIND(" ",клиенты!$K34,1)+1,(FIND(" ",клиенты!$K34,FIND(" ",клиенты!$K34,1)+1)-1)-FIND(" ",клиенты!$K34,1)) -> Ефимович | N34: =RIGHT(K34,LEN(K34)-FIND(" ",клиенты!$K34,FIND(" ",клиенты!$K34,1)+1)) -> Алексеев
A35: 310 | B35: +992 349-223-5769 | C35: Феофан Гурьевич Дорофеев | D35: нет | E35: 44807 | F35: =LEFT(клиенты!$B35,LEN(клиенты!$B35)-13) -> +992 | G35: =_xlfn.XLOOKUP(клиенты!$F35,'коды стран'!$B$2:$B$7,'коды стран'!$A$2:$A$7,"не найдено",0) -> Таджикистан | H35: =_xlfn.MAXIFS(Продажи[дата создания чека],Продажи[id клиента],A35) -> 45267 | I35: =IFERROR((H35-E35)/30.4375,0) -> 15.112936 | J35: =IF(LEN(C35) - LEN(SUBSTITUTE(C35," ",""))<3,C35,RIGHT(C35,LEN(C35)-FIND(" ",клиенты!$C35,1))) -> Феофан Гурьевич Дорофеев | K35: =IF(OR( RIGHT(MID(C35,FIND(" ",C35)+1,FIND(" ",C35,FIND(" ",C35)+1)-FIND(" ",C35)-1),2)="ич", RIGHT(MID(C35,FIND(" ",C35)+1,FIND(" ",C35,FIND(" ",C35)+1)-FIND(" ",C35)-1),3)="вна", RIGHT(MID(C35,FIND(" ",C35)+1,FIND(" ",C35,FIND(" ",C35)+1)-FIND(" ",C35)-1),3)="чна" ), C35, MID(C35,FIND(" ",C35)+1,FIND(" ",C35,FIND(" ",C35)+1)-FIND(" ",C35)-1)&" "& RIGHT(C35,LEN(C35)-FIND("☐",SUBSTITUTE(C35," ","☐",2)))&" "& LEFT(C35,FIND(" ",C35)-1) ) -> Феофан Гурьевич Дорофеев | L35: =LEFT(клиенты!$K35,FIND(" ",клиенты!$K35,1)-1) -> Феофан | M35: =MID(K35,FIND(" ",клиенты!$K35,1)+1,(FIND(" ",клиенты!$K35,FIND(" ",клиенты!$K35,1)+1)-1)-FIND(" ",клиенты!$K35,1)) -> Гурьевич | N35: =RIGHT(K35,LEN(K35)-FIND(" ",клиенты!$K35,FIND(" ",клиенты!$K35,1)+1)) -> Дорофеев
A36: 179 | B36: +7 747-678-7543 | C36: Капустина Тамара Валериевна | D36: да | E36: 44833 | F36: =LEFT(клиенты!$B36,LEN(клиенты!$B36)-13) -> +7 | G36: =_xlfn.XLOOKUP(клиенты!$F36,'коды стран'!$B$2:$B$7,'коды стран'!$A$2:$A$7,"не найдено",0) -> Россия | H36: =_xlfn.MAXIFS(Продажи[дата создания чека],Продажи[id клиента],A36) -> 45381 | I36: =IFERROR((H36-E36)/30.4375,0) -> 18.004107 | J36: =IF(LEN(C36) - LEN(SUBSTITUTE(C36," ",""))<3,C36,RIGHT(C36,LEN(C36)-FIND(" ",клиенты!$C36,1))) -> Капустина Тамара Валериевна | K36: =IF(OR( RIGHT(MID(C36,FIND(" ",C36)+1,FIND(" ",C36,FIND(" ",C36)+1)-FIND(" ",C36)-1),2)="ич", RIGHT(MID(C36,FIND(" ",C36)+1,FIND(" ",C36,FIND(" ",C36)+1)-FIND(" ",C36)-1),3)="вна", RIGHT(MID(C36,FIND(" ",C36)+1,FIND(" ",C36,FIND(" ",C36)+1)-FIND(" ",C36)-1),3)="чна" ), C36, MID(C36,FIND(" ",C36)+1,FIND(" ",C36,FIND(" ",C36)+1)-FIND(" ",C36)-1)&" "& RIGHT(C36,LEN(C36)-FIND("☐",SUBSTITUTE(C36," ","☐",2)))&" "& LEFT(C36,FIND(" ",C36)-1) ) -> Тамара Валериевна Капустина | L36: =LEFT(клиенты!$K36,FIND(" ",клиенты!$K36,1)-1) -> Тамара | M36: =MID(K36,FIND(" ",клиенты!$K36,1)+1,(FIND(" ",клиенты!$K36,FIND(" ",клиенты!$K36,1)+1)-1)-FIND(" ",клиенты!$K36,1)) -> Валериевна | N36: =RIGHT(K36,LEN(K36)-FIND(" ",клиенты!$K36,FIND(" ",клиенты!$K36,1)+1)) -> Капустина
A37: 64 | B37: +998 488-220-8790 | C37: Ратибор Арсеньевич Петров | D37: да | E37: 44707 | F37: =LEFT(клиенты!$B37,LEN(клиенты!$B37)-13) -> +998 | G37: =_xlfn.XLOOKUP(клиенты!$F37,'коды стран'!$B$2:$B$7,'коды стран'!$A$2:$A$7,"не найдено",0) -> Узбекистан | H37: =_xlfn.MAXIFS(Продажи[дата создания чека],Продажи[id клиента],A37) -> 45189 | I37: =IFERROR((H37-E37)/30.4375,0) -> 15.835729 | J37: =IF(LEN(C37) - LEN(SUBSTITUTE(C37," ",""))<3,C37,RIGHT(C37,LEN(C37)-FIND(" ",клиенты!$C37,1))) -> Ратибор Арсеньевич Петров | K37: =IF(OR( RIGHT(MID(C37,FIND(" ",C37)+1,FIND(" ",C37,FIND(" ",C37)+1)-FIND(" ",C37)-1),2)="ич", RIGHT(MID(C37,FIND(" ",C37)+1,FIND(" ",C37,FIND(" ",C37)+1)-FIND(" ",C37)-1),3)="вна", RIGHT(MID(C37,FIND(" ",C37)+1,FIND(" ",C37,FIND(" ",C37)+1)-FIND(" ",C37)-1),3)="чна" ), C37, MID(C37,FIND(" ",C37)+1,FIND(" ",C37,FIND(" ",C37)+1)-FIND(" ",C37)-1)&" "& RIGHT(C37,LEN(C37)-FIND("☐",SUBSTITUTE(C37," ","☐",2)))&" "& LEFT(C37,FIND(" ",C37)-1) ) -> Ратибор Арсеньевич Петров | L37: =LEFT(клиенты!$K37,FIND(" ",клиенты!$K37,1)-1) -> Ратибор | M37: =MID(K37,FIND(" ",клиенты!$K37,1)+1,(FIND(" ",клиенты!$K37,FIND(" ",клиенты!$K37,1)+1)-1)-FIND(" ",клиенты!$K37,1)) -> Арсеньевич | N37: =RIGHT(K37,LEN(K37)-FIND(" ",клиенты!$K37,FIND(" ",клиенты!$K37,1)+1)) -> Петров
A38: 318 | B38: +998 826-456-9884 | C38: Поляков Боян Андреевич | D38: да | E38: 44892 | F38: =LEFT(клиенты!$B38,LEN(клиенты!$B38)-13) -> +998 | G38: =_xlfn.XLOOKUP(клиенты!$F38,'коды стран'!$B$2:$B$7,'коды стран'!$A$2:$A$7,"не найдено",0) -> Узбекистан | H38: =_xlfn.MAXIFS(Продажи[дата создания чека],Продажи[id клиента],A38) -> 44993 | I38: =IFERROR((H38-E38)/30.4375,0) -> 3.3182752 | J38: =IF(LEN(C38) - LEN(SUBSTITUTE(C38," ",""))<3,C38,RIGHT(C38,LEN(C38)-FIND(" ",клиенты!$C38,1))) -> Поляков Боян Андреевич | K38: =IF(OR( RIGHT(MID(C38,FIND(" ",C38)+1,FIND(" ",C38,FIND(" ",C38)+1)-FIND(" ",C38)-1),2)="ич", RIGHT(MID(C38,FIND(" ",C38)+1,FIND(" ",C38,FIND(" ",C38)+1)-FIND(" ",C38)-1),3)="вна", RIGHT(MID(C38,FIND(" ",C38)+1,FIND(" ",C38,FIND(" ",C38)+1)-FIND(" ",C38)-1),3)="чна" ), C38, MID(C38,FIND(" ",C38)+1,FIND(" ",C38,FIND(" ",C38)+1)-FIND(" ",C38)-1)&" "& RIGHT(C38,LEN(C38)-FIND("☐",SUBSTITUTE(C38," ","☐",2)))&" "& LEFT(C38,FIND(" ",C38)-1) ) -> Боян Андреевич Поляков | L38: =LEFT(клиенты!$K38,FIND(" ",клиенты!$K38,1)-1) -> Боян | M38: =MID(K38,FIND(" ",клиенты!$K38,1)+1,(FIND(" ",клиенты!$K38,FIND(" ",клиенты!$K38,1)+1)-1)-FIND(" ",клиенты!$K38,1)) -> Андреевич | N38: =RIGHT(K38,LEN(K38)-FIND(" ",клиенты!$K38,FIND(" ",клиенты!$K38,1)+1)) -> Поляков
... A435: 427 | B435: +7 630-011-3417 | C435: Лидия Андреевна Крюкова | D435: нет | E435: 44834 | F435: =LEFT(клиенты!$B435,LEN(клиенты!$B435)-13) -> +7 | G435: =_xlfn.XLOOKUP(клиенты!$F435,'коды стран'!$B$2:$B$7,'коды стран'!$A$2:$A$7,"не найдено",0) -> Россия | H435: =_xlfn.MAXIFS(Продажи[дата создания чека],Продажи[id клиента],A435) -> 45377 | I435: =IFERROR((H435-E435)/30.4375,0) -> 17.839836 | J435: =IF(LEN(C435) - LEN(SUBSTITUTE(C435," ",""))<3,C435,RIGHT(C435,LEN(C435)-FIND(" ",клиенты!$C435,1))) -> Лидия Андреевна Крюкова | K435: =IF(OR( RIGHT(MID(C435,FIND(" ",C435)+1,FIND(" ",C435,FIND(" ",C435)+1)-FIND(" ",C435)-1),2)="ич", RIGHT(MID(C435,FIND(" ",C435)+1,FIND(" ",C435,FIND(" ",C435)+1)-FIND(" ",C435)-1),3)="вна", RIGHT(MID(C435,FIND(" ",C435)+1,FIND(" ",C435,FIND(" ",C435)+1)-FIND(" ",C435)-1),3)="чна" ), C435, MID(C435,FIND(" ",C435)+1,FIND(" ",C435,FIND(" ",C435)+1)-FIND(" ",C435)-1)&" "& RIGHT(C435,LEN(C435)-FIND("☐",SUBSTITUTE(C435," ","☐",2)))&" "& LEFT(C435,FIND(" ",C435)-1) ) -> Лидия Андреевна Крюкова | L435: =LEFT(клиенты!$K435,FIND(" ",клиенты!$K435,1)-1) -> Лидия | M435: =MID(K435,FIND(" ",клиенты!$K435,1)+1,(FIND(" ",клиенты!$K435,FIND(" ",клиенты!$K435,1)+1)-1)-FIND(" ",клиенты!$K435,1)) -> Андреевна | N435: =RIGHT(K435,LEN(K435)-FIND(" ",клиенты!$K435,FIND(" ",клиенты!$K435,1)+1)) -> Крюкова

Sheet товар
A1: id товара | B1: категория товара | C1: поставщик
A2: 300 | B2: Сахар | C2: Продимекс
A3: 486 | B3: Соль | C3: Илецкая
A4: 76 | B4: Печенье | C4: Юбилейное
A5: 240 | B5: Макароны | C5: Борилла
A6: 32 | B6: Овощи | C6: Зеленая грядка
A7: 162 | B7: Сок | C7: Фруктовый сад
A8: 323 | B8: Рыба | C8: Меридиан
A9: 60 | B9: Кофе | C9: Jacobs
A10: 401 | B10: Чай | C10: Greenfield
A11: 100 | B11: Йогурт | C11: Ростагроэкспорт
A12: 217 | B12: Мясо | C12: Агрокомплекс
A13: 445 | B13: Сахар | C13: Сладов
... A433: 469 | B433: Сахар | C433: Сладов

Sheet лайфтайм клиента
A1: ID уникальный | B1: 1 | D1: =LARGE(B:B,1) -> 62 | E1: =_xlfn.XLOOKUP(D1,B:B,A:A,"не найдено",0) -> 15-17
D2: =SMALL(B:B,2) -> 5 | E2: =_xlfn.XLOOKUP(D2,B4:B271,A4:A271,"не найдено",0) -> 1-3
A3: Названия строк | B3: Сумма по полю ID уникальный
A4: 1-3 | B4: 5
A5: 3-5 | B5: 7
A6: 5-7 | B6: 8
A7: 7-9 | B7: 13
A8: 9-11 | B8: 24
A9: 11-13 | B9: 44
A10: 13-15 | B10: 45
A11: 15-17 | B11: 62
A12: 17-19 | B12: 60
A13: 19-21 | B13: 58
A14: 21-23 | B14: 49
A15: 23-25 | B15: 35
... A17: 27-29 | B17: 7
C30: Наибольшее число клиентов были зарегистрированы в период | D30: =_xlfn.XLOOKUP(D1,B:B,A:A,"не найдено",0) -> 15-17 | E30: месяцев, наименьшее - в период | F30: =_xlfn.XLOOKUP(D2,B4:B271,A4:A271,"не найдено",0) -> 1-3 | G30: месяцев.

Sheet география клиентов
A3: Названия строк | B3: Сумма по полю ID уникальный
A4: Россия | B4: 146
A5: Узбекистан | B5: 85
A6: Украина | B6: 78
A7: Таджикистан | B7: 74
A8: Беларусь | B8: 51
A13: Названия строк | B13: Сумма по полю ID уникальный
A14: Россия | B14: 0.33640553
A15: Узбекистан | B15: 0.19585253
A16: Украина | B16: 0.1797235
A17: Таджикистан | B17: 0.17050691
A18: Беларусь | B18: 0.11751152
A19: Общий итог | B19: 1 | D19: Большинство клиентов торговых сетей из России - 34% от общего числа клиентов или 146 чел., меньше всего из Беларуси - 12% или 51 чел.

Sheet продажи магазинов
A1: магазин покупки | B1: (Все)
A3: Период | B3: Сумма по полю сумма чека
A4: 2023 | B4: 2908895
A5: янв | B5: 240500
A6: фев | B6: 210180
A7: мар | B7: 251740
A8: апр | B8: 279760
A9: май | B9: 210500
A10: июн | B10: 264125
A11: июл | B11: 245855
A12: авг | B12: 294065
A13: сен | B13: 259360
A14: окт | B14: 185800
A15: ноя | B15: 215925
... A23: Общий итог | B23: 4002165
D29: Динамика продаж с января 2023г. по май 2024 г. характеризуется значительными колебаниями. В 2023 г. особенно сильная просадка продаж наблюдается в октябре - до 185 800 у.е. Пик продаж пришелся на март 2024 и достиг 299 875 у.е., что может быть связано с успешно проведенными акциями или запуском нового продукта. Затем наблюдался спад продаж и к маю 2024 г. продажи достигли своего минимума 118 215 у.е. (-181 660 у.е. за 2 месяца), что связано с отсутствием в мае 2024 г. данных о продажах 8 ТС (Мосмарт, Верный, Седьмой Континент, Бристоль, Мираторг, Магнит, Дикси, Пятёрочка).

Sheet Магнит
A1: магазин покупки | B1: Магнит
A3: Период | B3: Сумма по полю сумма чека
A4: 2023 | B4: 119865
A5: янв | B5: 14415
A6: фев | B6: 10055
A7: мар | B7: 12625
A8: апр | B8: 17375
A9: май | B9: 1780
A10: июн | B10: 10065
A11: июл | B11: 17185
A12: авг | B12: 13510
A13: сен | B13: 13585
A14: ноя | B14: 2690
A15: дек | B15: 6580
... A21: Общий итог | B21: 188180
D29: Для ТС Магнит за анализируемый период характерны два особо сильных спада продаж в мае и ноябре 2023 г. В мае объем продаж снизился на 3 119 у.е. или почти в 10 раз по сравнению с прошлым месяцем и составил 356 у.е. С ноября 2023 г. по апрель 2024 г. сохраняется тенденция роста объема продаж, который достиг своего максимума в мае 2024 г. - 4 950 у.е. В мае 2024 г. нет данных по продажам в ТС Магнит
